[2023-05-01T13:34:33.773+0000] {taskinstance.py:1090} INFO - Dependencies all met for dep_context=non-requeueable deps ti=<TaskInstance: space_missions_launches_to_gcp_dag.space_missions_launches_to_gcp_task manual__2023-05-01T11:30:38.175260+00:00 [queued]>
[2023-05-01T13:34:33.778+0000] {taskinstance.py:1090} INFO - Dependencies all met for dep_context=requeueable deps ti=<TaskInstance: space_missions_launches_to_gcp_dag.space_missions_launches_to_gcp_task manual__2023-05-01T11:30:38.175260+00:00 [queued]>
[2023-05-01T13:34:33.778+0000] {taskinstance.py:1288} INFO - 
--------------------------------------------------------------------------------
[2023-05-01T13:34:33.778+0000] {taskinstance.py:1289} INFO - Starting attempt 12 of 12
[2023-05-01T13:34:33.778+0000] {taskinstance.py:1290} INFO - 
--------------------------------------------------------------------------------
[2023-05-01T13:34:33.786+0000] {taskinstance.py:1309} INFO - Executing <Task(PythonOperator): space_missions_launches_to_gcp_task> on 2023-05-01 11:30:38.175260+00:00
[2023-05-01T13:34:33.791+0000] {standard_task_runner.py:55} INFO - Started process 8264 to run task
[2023-05-01T13:34:33.792+0000] {standard_task_runner.py:82} INFO - Running: ['***', 'tasks', 'run', 'space_missions_launches_to_gcp_dag', 'space_missions_launches_to_gcp_task', 'manual__2023-05-01T11:30:38.175260+00:00', '--job-id', '26', '--raw', '--subdir', 'DAGS_FOLDER/space_missions_launches_to_gcp.py', '--cfg-path', '/tmp/tmp3yy9n7x0']
[2023-05-01T13:34:33.793+0000] {standard_task_runner.py:83} INFO - Job 26: Subtask space_missions_launches_to_gcp_task
[2023-05-01T13:34:33.827+0000] {task_command.py:389} INFO - Running <TaskInstance: space_missions_launches_to_gcp_dag.space_missions_launches_to_gcp_task manual__2023-05-01T11:30:38.175260+00:00 [running]> on host e47d5c97588c
[2023-05-01T13:34:33.868+0000] {taskinstance.py:1518} INFO - Exporting the following env vars:
AIRFLOW_CTX_DAG_OWNER=viktoria.k
AIRFLOW_CTX_DAG_ID=space_missions_launches_to_gcp_dag
AIRFLOW_CTX_TASK_ID=space_missions_launches_to_gcp_task
AIRFLOW_CTX_EXECUTION_DATE=2023-05-01T11:30:38.175260+00:00
AIRFLOW_CTX_TRY_NUMBER=12
AIRFLOW_CTX_DAG_RUN_ID=manual__2023-05-01T11:30:38.175260+00:00
[2023-05-01T13:34:33.874+0000] {base.py:73} INFO - Using connection ID 'google_cloud_default' for task execution.
[2023-05-01T13:34:34.495+0000] {taskinstance.py:1776} ERROR - Task failed with exception
Traceback (most recent call last):
  File "/home/airflow/.local/lib/python3.7/site-packages/pandas/core/tools/datetimes.py", line 509, in _to_datetime_with_format
    values, tz = conversion.datetime_to_datetime64(arg)
  File "pandas/_libs/tslibs/conversion.pyx", line 359, in pandas._libs.tslibs.conversion.datetime_to_datetime64
TypeError: Unrecognized value type: <class 'str'>

During handling of the above exception, another exception occurred:

Traceback (most recent call last):
  File "/home/airflow/.local/lib/python3.7/site-packages/airflow/operators/python.py", line 175, in execute
    return_value = self.execute_callable()
  File "/home/airflow/.local/lib/python3.7/site-packages/airflow/operators/python.py", line 192, in execute_callable
    return self.python_callable(*self.op_args, **self.op_kwargs)
  File "/opt/airflow/dags/space_missions_launches_to_gcp.py", line 30, in mission_launches_to_gcp
    mission_launches = transform_spase_mission_file(mission_launches)
  File "/opt/airflow/dags/utils/missions_launches_transformation_script.py", line 20, in transform_spase_mission_file
    missions_data['Date'] = pd.to_datetime(missions_data['Date'], format='mixed')
  File "/home/airflow/.local/lib/python3.7/site-packages/pandas/core/tools/datetimes.py", line 887, in to_datetime
    values = convert_listlike(arg._values, format)
  File "/home/airflow/.local/lib/python3.7/site-packages/pandas/core/tools/datetimes.py", line 394, in _convert_listlike_datetimes
    arg, orig_arg, name, tz, format, exact, errors, infer_datetime_format
  File "/home/airflow/.local/lib/python3.7/site-packages/pandas/core/tools/datetimes.py", line 513, in _to_datetime_with_format
    raise err
  File "/home/airflow/.local/lib/python3.7/site-packages/pandas/core/tools/datetimes.py", line 501, in _to_datetime_with_format
    arg, name, tz, fmt, exact, errors, infer_datetime_format
  File "/home/airflow/.local/lib/python3.7/site-packages/pandas/core/tools/datetimes.py", line 436, in _array_strptime_with_fallback
    result, timezones = array_strptime(arg, fmt, exact=exact, errors=errors)
  File "pandas/_libs/tslibs/strptime.pyx", line 150, in pandas._libs.tslibs.strptime.array_strptime
ValueError: time data 'Fri Aug 07, 2020 05:12 UTC' does not match format 'mixed' (match)
[2023-05-01T13:34:34.501+0000] {taskinstance.py:1332} INFO - Marking task as FAILED. dag_id=space_missions_launches_to_gcp_dag, task_id=space_missions_launches_to_gcp_task, execution_date=20230501T113038, start_date=20230501T133433, end_date=20230501T133434
[2023-05-01T13:34:34.510+0000] {standard_task_runner.py:105} ERROR - Failed to execute job 26 for task space_missions_launches_to_gcp_task (time data 'Fri Aug 07, 2020 05:12 UTC' does not match format 'mixed' (match); 8264)
[2023-05-01T13:34:34.526+0000] {local_task_job.py:212} INFO - Task exited with return code 1
[2023-05-01T13:34:34.537+0000] {taskinstance.py:2596} INFO - 0 downstream tasks scheduled from follow-on schedule check
